{
 "cells": [
  {
   "cell_type": "code",
   "execution_count": 4,
   "id": "51bf1ca5",
   "metadata": {
    "ExecuteTime": {
     "end_time": "2022-03-09T12:32:38.671271Z",
     "start_time": "2022-03-09T12:30:40.958610Z"
    }
   },
   "outputs": [
    {
     "name": "stdout",
     "output_type": "stream",
     "text": [
      "Collecting plotly\n"
     ]
    },
    {
     "name": "stderr",
     "output_type": "stream",
     "text": [
      "  WARNING: Retrying (Retry(total=4, connect=None, read=None, redirect=None, status=None)) after connection broken by 'ConnectTimeoutError(<pip._vendor.urllib3.connection.HTTPSConnection object at 0x000001EF74540D60>, 'Connection to files.pythonhosted.org timed out. (connect timeout=15)')': /packages/9f/16/c63412aec59219142b541011524417ef1c1c226e4a5ed2eb1cd808cd1a2b/plotly-5.6.0-py2.py3-none-any.whl\n",
      "  WARNING: Retrying (Retry(total=3, connect=None, read=None, redirect=None, status=None)) after connection broken by 'ConnectTimeoutError(<pip._vendor.urllib3.connection.HTTPSConnection object at 0x000001EF74540400>, 'Connection to files.pythonhosted.org timed out. (connect timeout=15)')': /packages/9f/16/c63412aec59219142b541011524417ef1c1c226e4a5ed2eb1cd808cd1a2b/plotly-5.6.0-py2.py3-none-any.whl\n",
      "  WARNING: Retrying (Retry(total=2, connect=None, read=None, redirect=None, status=None)) after connection broken by 'ConnectTimeoutError(<pip._vendor.urllib3.connection.HTTPSConnection object at 0x000001EF74540DF0>, 'Connection to files.pythonhosted.org timed out. (connect timeout=15)')': /packages/9f/16/c63412aec59219142b541011524417ef1c1c226e4a5ed2eb1cd808cd1a2b/plotly-5.6.0-py2.py3-none-any.whl\n",
      "  WARNING: Retrying (Retry(total=1, connect=None, read=None, redirect=None, status=None)) after connection broken by 'ConnectTimeoutError(<pip._vendor.urllib3.connection.HTTPSConnection object at 0x000001EF74540A30>, 'Connection to files.pythonhosted.org timed out. (connect timeout=15)')': /packages/9f/16/c63412aec59219142b541011524417ef1c1c226e4a5ed2eb1cd808cd1a2b/plotly-5.6.0-py2.py3-none-any.whl\n",
      "  WARNING: Retrying (Retry(total=0, connect=None, read=None, redirect=None, status=None)) after connection broken by 'ConnectTimeoutError(<pip._vendor.urllib3.connection.HTTPSConnection object at 0x000001EF74540E80>, 'Connection to files.pythonhosted.org timed out. (connect timeout=15)')': /packages/9f/16/c63412aec59219142b541011524417ef1c1c226e4a5ed2eb1cd808cd1a2b/plotly-5.6.0-py2.py3-none-any.whl\n",
      "ERROR: Could not install packages due to an EnvironmentError: HTTPSConnectionPool(host='files.pythonhosted.org', port=443): Max retries exceeded with url: /packages/9f/16/c63412aec59219142b541011524417ef1c1c226e4a5ed2eb1cd808cd1a2b/plotly-5.6.0-py2.py3-none-any.whl (Caused by ConnectTimeoutError(<pip._vendor.urllib3.connection.HTTPSConnection object at 0x000001EF745400D0>, 'Connection to files.pythonhosted.org timed out. (connect timeout=15)'))\n",
      "\n"
     ]
    },
    {
     "ename": "ModuleNotFoundError",
     "evalue": "No module named 'plotly'",
     "output_type": "error",
     "traceback": [
      "\u001b[1;31m---------------------------------------------------------------------------\u001b[0m",
      "\u001b[1;31mModuleNotFoundError\u001b[0m                       Traceback (most recent call last)",
      "\u001b[1;32m<ipython-input-4-5502c6ab6c8f>\u001b[0m in \u001b[0;36m<module>\u001b[1;34m\u001b[0m\n\u001b[0;32m      1\u001b[0m \u001b[0mget_ipython\u001b[0m\u001b[1;33m(\u001b[0m\u001b[1;33m)\u001b[0m\u001b[1;33m.\u001b[0m\u001b[0msystem\u001b[0m\u001b[1;33m(\u001b[0m\u001b[1;34m'pip install plotly'\u001b[0m\u001b[1;33m)\u001b[0m\u001b[1;33m\u001b[0m\u001b[1;33m\u001b[0m\u001b[0m\n\u001b[0;32m      2\u001b[0m \u001b[1;32mimport\u001b[0m \u001b[0mpandas\u001b[0m \u001b[1;32mas\u001b[0m \u001b[0mpd\u001b[0m\u001b[1;33m\u001b[0m\u001b[1;33m\u001b[0m\u001b[0m\n\u001b[1;32m----> 3\u001b[1;33m \u001b[1;32mimport\u001b[0m \u001b[0mplotly\u001b[0m\u001b[1;33m.\u001b[0m\u001b[0mexpress\u001b[0m \u001b[1;32mas\u001b[0m \u001b[0mpx\u001b[0m\u001b[1;33m\u001b[0m\u001b[1;33m\u001b[0m\u001b[0m\n\u001b[0m\u001b[0;32m      4\u001b[0m \u001b[1;33m\u001b[0m\u001b[0m\n\u001b[0;32m      5\u001b[0m \u001b[1;31m#以下路径替换为自己的\u001b[0m\u001b[1;33m\u001b[0m\u001b[1;33m\u001b[0m\u001b[1;33m\u001b[0m\u001b[0m\n",
      "\u001b[1;31mModuleNotFoundError\u001b[0m: No module named 'plotly'"
     ]
    }
   ],
   "source": [
    "!pip install plotly\n",
    "import pandas as pd\n",
    "import plotly.express as px\n",
    "\n",
    "#以下路径替换为自己的\n",
    "data = pd.read_excel(\"C:/Users/admin/PycharmProjects/Game/旭日图.xlsx\")\n",
    "data.head()\n",
    "fig = px.sunburst(data, path=['地区', '省/自治区', '城市'], \n",
    "                  values='数量', color='数量')\n",
    "fig.show()"
   ]
  },
  {
   "cell_type": "code",
   "execution_count": null,
   "id": "8e05170b",
   "metadata": {},
   "outputs": [],
   "source": []
  }
 ],
 "metadata": {
  "kernelspec": {
   "display_name": "Python [conda env:root]",
   "language": "python",
   "name": "conda-root-py"
  },
  "language_info": {
   "codemirror_mode": {
    "name": "ipython",
    "version": 3
   },
   "file_extension": ".py",
   "mimetype": "text/x-python",
   "name": "python",
   "nbconvert_exporter": "python",
   "pygments_lexer": "ipython3",
   "version": "3.8.5"
  },
  "toc": {
   "base_numbering": 1,
   "nav_menu": {},
   "number_sections": true,
   "sideBar": true,
   "skip_h1_title": false,
   "title_cell": "Table of Contents",
   "title_sidebar": "Contents",
   "toc_cell": false,
   "toc_position": {},
   "toc_section_display": true,
   "toc_window_display": false
  }
 },
 "nbformat": 4,
 "nbformat_minor": 5
}
